<?xml version="1.0"?>
<robot>
     <macro name="cylinder_inertia" params="m r h">
        <inertia  ixx="0.01" ixy = "0" ixz = "0"
                  iyy="0.01" iyz = "0"
                  izz="0.01" /> 
      </macro>

      <macro name="box_inertia" params="m x y z">
        <inertia  ixx="1" ixy = "0" ixz = "0"
                  iyy="1" iyz = "0"
                  izz="1" /> 
      </macro>

<!--    <macro name="sphere_inertia" params="m r">
        <inertia  ixx="${2*m*r*r/5}" ixy = "0" ixz = "0"
                  iyy="${2*m*r*r/5}" iyz = "0"
                  izz="${2*m*r*r/5}" /> 
      </macro>
-->
     <macro name="wheel" params="lr tY tx">

       <link name="${lr}_wheel">
        <collision>
          <origin xyz="0 0 0" rpy="0 ${PI/2} ${PI/2}" />
          <geometry>
           <cylinder length="${wheelWidth}" radius="${wheelRadius}"/>
          </geometry>
        </collision>

        <visual>
          <origin xyz="0 0 0" rpy="0 ${PI/2} ${PI/2}" />
          <geometry>
           <cylinder length="${wheelWidth}" radius="${wheelRadius}"/>
          </geometry>
          <material name="black"/>
        </visual>

        <inertial>
          <origin xyz="0 0 0" rpy="0 ${PI/2} ${PI/2}" />
          <mass value="${wheelMass}"/>
          <cylinder_inertia m="${wheelMass}" r="${wheelRadius}" h="${wheelWidth}"/>
        </inertial>
       </link>

        <gazebo reference="${lr}_wheel">
          <mu1 value="1000.0"/>
          <mu2 value="1000.0"/>
          <kp  value="10000000.0" />
          <kd  value="1.0" />
          <fdir1 value="1 0 0"/>
          <material>Gazebo/Black</material>
        </gazebo>


       <joint name="${lr}_wheel_hinge" type="continuous">
          <parent link="chassis"/>
          <child link="${lr}_wheel"/>
          <origin xyz="${+tx} ${tY} 0" rpy="0 0 0" /> 
          <axis xyz="0 1 0" rpy="0 0 0" />
          <limit effort="100" velocity="100"/>
          <joint_properties damping="0.0" friction="0.0"/>
        </joint>


        <transmission name="${lr}_trans">
        <type>transmission_interface/SimpleTransmission</type>
        <joint name="${lr}_wheel_hinge">
	       <hardware_interface>hardware_interface/EffortJointInterface</hardware_interface>
	    </joint>
        <actuator name="${lr}Motor">
          <hardware_interface>hardware_interface/EffortJointInterface</hardware_interface>
          <mechanicalReduction>10</mechanicalReduction>
         </actuator>
      </transmission>


         </macro>

</robot>
